Workbook
Name NativeTimeline_Día1: #N/A
Name NativeTimeline_Fecha: #N/A
Name SegmentaciónDeDatos_P_LC_CF_CL1: #N/A

Sheet Hoja1
A3: Semana | B3: Meses (Día) | C3: Días (Día) | D3: Día | E3: Cuenta de Tiempo producción | F3: Suma de Tiempo producción
A4: 12 | B4: mar | C4: 17-mar | D4: 45733 | E4: 4 | F4: 0.60763889
C5: 17-mar Total | E5: 4 | F5: 0.60763889
C6: 18-mar | D6: 45734 | E6: 6 | F6: 0.58333333
C7: 18-mar Total | E7: 6 | F7: 0.58333333
C8: 19-mar | D8: 45735 | E8: 4 | F8: 0.60763889
C9: 19-mar Total | E9: 4 | F9: 0.60763889
C10: 20-mar | D10: 45736 | E10: 3 | F10: 0.52986111
C11: 20-mar Total | E11: 3 | F11: 0.52986111
C12: 21-mar | D12: 45737 | E12: 4 | F12: 0.09375
C13: 21-mar Total | E13: 4 | F13: 0.09375
B14: mar Total | E14: 21 | F14: 2.4222222
A15: 12 Total | E15: 21 | F15: 2.4222222
A16: 13 | B16: mar | C16: 24-mar | D16: 45740 | E16: 3 | F16: 0.38888889
C17: 24-mar Total | E17: 3 | F17: 0.38888889
C18: 25-mar | D18: 45741 | E18: 5 | F18: 0.23611111
C19: 25-mar Total | E19: 5 | F19: 0.23611111
C20: 26-mar | D20: 45742 | E20: 3 | F20: 0.46875
C21: 26-mar Total | E21: 3 | F21: 0.46875
C22: 27-mar | D22: 45743 | E22: 2 | F22: 0.59375
C23: 27-mar Total | E23: 2 | F23: 0.59375
C24: 28-mar | D24: 45744 | E24: 1 | F24: 0.024305556
C25: 28-mar Total | E25: 1 | F25: 0.024305556
B26: mar Total | E26: 14 | F26: 1.7118056
A27: 13 Total | E27: 14 | F27: 1.7118056
A28: 15 | B28: abr | C28: 11-abr | D28: 45758 | E28: 1 | F28: 0
C29: 11-abr Total | E29: 1 | F29: 0
B30: abr Total | E30: 1 | F30: 0
A31: 15 Total | E31: 1 | F31: 0
A32: 16 | B32: abr | C32: 14-abr | D32: 45761 | E32: 1 | F32: 0
C33: 14-abr Total | E33: 1 | F33: 0
C34: 15-abr | D34: 45762 | E34: 1 | F34: 0
C35: 15-abr Total | E35: 1 | F35: 0
C36: 16-abr | D36: 45763 | E36: 1 | F36: 0
C37: 16-abr Total | E37: 1 | F37: 0
B38: abr Total | E38: 3 | F38: 0
A39: 16 Total | E39: 3 | F39: 0
A40: 17 | B40: abr | C40: 22-abr | D40: 45769 | E40: 2 | F40: 0.33333333
C41: 22-abr Total | E41: 2 | F41: 0.33333333
C42: 23-abr | D42: 45770 | E42: 1 | F42: 0.66666667
...

Sheet Hoja2
H1: =IF(G1>1,"V","F") -> F
D2: 1800 | F2: 0.625
A3: Row Labels | B3: Suma de Tiempo producción | C3: Cantidad producida | D3: Cantidad teórica | E3: Rendimiento | F3: Disponibilidad | G3: Fallos disponibilidad
A4: 12 | B4: 2.4222222 | D4: =IF(A4<53,"",IFERROR(((HOUR(B4)*60+MINUTE(B4))/60)*$D$2,"")) | E4: =IFERROR(C4/D4,"") | F4: =IF(A4<53,"",IFERROR(B4/$F$2,"")) | G4: =IF(F4="","",IF(F4>1,"NO",""))
A5: 13 | B5: 1.7118056 | D5: =IF(A5<53,"",IFERROR(((HOUR(B5)*60+MINUTE(B5))/60)*$D$2,"")) | E5: =IFERROR(C5/D5,"") | F5: =IF(A5<53,"",IFERROR(B5/$F$2,"")) | G5: =IF(F5="","",IF(F5>1,"NO",""))
A6: 15 | B6: 0 | D6: =IF(A6<53,"",IFERROR(((HOUR(B6)*60+MINUTE(B6))/60)*$D$2,"")) | E6: =IFERROR(C6/D6,"") | F6: =IF(A6<53,"",IFERROR(B6/$F$2,"")) | G6: =IF(F6="","",IF(F6>1,"NO",""))
A7: 16 | B7: 0 | D7: =IF(A7<53,"",IFERROR(((HOUR(B7)*60+MINUTE(B7))/60)*$D$2,"")) | E7: =IFERROR(C7/D7,"") | F7: =IF(A7<53,"",IFERROR(B7/$F$2,"")) | G7: =IF(F7="","",IF(F7>1,"NO",""))
A8: 17 | B8: 2.0694444 | D8: =IF(A8<53,"",IFERROR(((HOUR(B8)*60+MINUTE(B8))/60)*$D$2,"")) | E8: =IFERROR(C8/D8,"") | F8: =IF(A8<53,"",IFERROR(B8/$F$2,"")) | G8: =IF(F8="","",IF(F8>1,"NO",""))
A9: 18 | B9: 1.46875 | D9: =IF(A9<53,"",IFERROR(((HOUR(B9)*60+MINUTE(B9))/60)*$D$2,"")) | E9: =IFERROR(C9/D9,"") | F9: =IF(A9<53,"",IFERROR(B9/$F$2,"")) | G9: =IF(F9="","",IF(F9>1,"NO",""))
A10: 19 | B10: 2.09375 | D10: =IF(A10<53,"",IFERROR(((HOUR(B10)*60+MINUTE(B10))/60)*$D$2,"")) | E10: =IFERROR(C10/D10,"") | F10: =IF(A10<53,"",IFERROR(B10/$F$2,"")) | G10: =IF(F10="","",IF(F10>1,"NO",""))
A11: 20 | B11: 1.9201389 | D11: =IF(A11<53,"",IFERROR(((HOUR(B11)*60+MINUTE(B11))/60)*$D$2,"")) | E11: =IFERROR(C11/D11,"") | F11: =IF(A11<53,"",IFERROR(B11/$F$2,"")) | G11: =IF(F11="","",IF(F11>1,"NO",""))
A12: 21 | B12: 2.2013889 | D12: =IF(A12<53,"",IFERROR(((HOUR(B12)*60+MINUTE(B12))/60)*$D$2,"")) | E12: =IFERROR(C12/D12,"") | F12: =IF(A12<53,"",IFERROR(B12/$F$2,"")) | G12: =IF(F12="","",IF(F12>1,"NO",""))
A13: 22 | B13: 2.0069444 | D13: =IF(A13<53,"",IFERROR(((HOUR(B13)*60+MINUTE(B13))/60)*$D$2,"")) | E13: =IFERROR(C13/D13,"") | F13: =IF(A13<53,"",IFERROR(B13/$F$2,"")) | G13: =IF(F13="","",IF(F13>1,"NO",""))
A14: 23 | B14: 0.99652778 | D14: =IF(A14<53,"",IFERROR(((HOUR(B14)*60+MINUTE(B14))/60)*$D$2,"")) | E14: =IFERROR(C14/D14,"") | F14: =IF(A14<53,"",IFERROR(B14/$F$2,"")) | G14: =IF(F14="","",IF(F14>1,"NO",""))
A15: 6 | B15: 1.2569444 | D15: =IF(A15<53,"",IFERROR(((HOUR(B15)*60+MINUTE(B15))/60)*$D$2,"")) | E15: =IFERROR(C15/D15,"") | F15: =IF(A15<53,"",IFERROR(B15/$F$2,"")) | G15: =IF(F15="","",IF(F15>1,"NO",""))
... A27: 30 | B27: 1.2604167 | D27: =IF(A27<53,"",IFERROR(((HOUR(B27)*60+MINUTE(B27))/60)*$D$2,"")) | E27: =IFERROR(C27/D27,"") | F27: =IF(A27<53,"",IFERROR(B27/$F$2,"")) | G27: =IF(F27="","",IF(F27>1,"NO",""))
A28: Grand Total | B28: 33.691667 | D28: =IF(A28<53,"",IFERROR(((HOUR(B28)*60+MINUTE(B28))/60)*$D$2,"")) -> 29880 | E28: =IFERROR(C28/D28,"") -> 0 | F28: =IF(A28<53,"",IFERROR(B28/$F$2,"")) -> 53.906667 | G28: =IF(F28="","",IF(F28>1,"NO","")) -> NO
D29: =IF(A29<53,"",IFERROR(((HOUR(B29)*60+MINUTE(B29))/60)*$D$2,"")) | E29: =IFERROR(C29/D29,"") | F29: =IF(A29<53,"",IFERROR(B29/$F$2,"")) | G29: =IF(F29="","",IF(F29>1,"NO",""))
D30: =IF(A30<53,"",IFERROR(((HOUR(B30)*60+MINUTE(B30))/60)*$D$2,"")) | E30: =IFERROR(C30/D30,"") | F30: =IF(A30<53,"",IFERROR(B30/$F$2,"")) | G30: =IF(F30="","",IF(F30>1,"NO",""))
D31: =IF(A31<53,"",IFERROR(((HOUR(B31)*60+MINUTE(B31))/60)*$D$2,"")) | E31: =IFERROR(C31/D31,"") | F31: =IF(A31<53,"",IFERROR(B31/$F$2,"")) | G31: =IF(F31="","",IF(F31>1,"NO",""))
D32: =IF(A32<53,"",IFERROR(((HOUR(B32)*60+MINUTE(B32))/60)*$D$2,"")) | E32: =IFERROR(C32/D32,"") | F32: =IF(A32<53,"",IFERROR(B32/$F$2,"")) | G32: =IF(F32="","",IF(F32>1,"NO",""))
D33: =IF(A33<53,"",IFERROR(((HOUR(B33)*60+MINUTE(B33))/60)*$D$2,"")) | E33: =IFERROR(C33/D33,"") | F33: =IF(A33<53,"",IFERROR(B33/$F$2,"")) | G33: =IF(F33="","",IF(F33>1,"NO",""))
D34: =IF(A34<53,"",IFERROR(((HOUR(B34)*60+MINUTE(B34))/60)*$D$2,"")) | E34: =IFERROR(C34/D34,"") | F34: =IF(A34<53,"",IFERROR(B34/$F$2,"")) | G34: =IF(F34="","",IF(F34>1,"NO",""))
D35: =IF(A35<53,"",IFERROR(((HOUR(B35)*60+MINUTE(B35))/60)*$D$2,"")) | E35: =IFERROR(C35/D35,"") | F35: =IF(A35<53,"",IFERROR(B35/$F$2,"")) | G35: =IF(F35="","",IF(F35>1,"NO",""))
D36: =IF(A36<53,"",IFERROR(((HOUR(B36)*60+MINUTE(B36))/60)*$D$2,"")) | E36: =IFERROR(C36/D36,"") | F36: =IF(A36<53,"",IFERROR(B36/$F$2,"")) | G36: =IF(F36="","",IF(F36>1,"NO",""))
D37: =IF(A37<53,"",IFERROR(((HOUR(B37)*60+MINUTE(B37))/60)*$D$2,"")) | E37: =IFERROR(C37/D37,"") | F37: =IF(A37<53,"",IFERROR(B37/$F$2,"")) | G37: =IF(F37="","",IF(F37>1,"NO",""))
D38: =IF(A38<53,"",IFERROR(((HOUR(B38)*60+MINUTE(B38))/60)*$D$2,"")) | E38: =IFERROR(C38/D38,"") | F38: =IF(A38<53,"",IFERROR(B38/$F$2,"")) | G38: =IF(F38="","",IF(F38>1,"NO",""))
D39: =IF(A39<53,"",IFERROR(((HOUR(B39)*60+MINUTE(B39))/60)*$D$2,"")) | E39: =IFERROR(C39/D39,"") | F39: =IF(A39<53,"",IFERROR(B39/$F$2,"")) | G39: =IF(F39="","",IF(F39>1,"NO",""))
D40: =IF(A40<53,"",IFERROR(((HOUR(B40)*60+MINUTE(B40))/60)*$D$2,"")) | E40: =IFERROR(C40/D40,"") | F40: =IF(A40<53,"",IFERROR(B40/$F$2,"")) | G40: =IF(F40="","",IF(F40>1,"NO",""))
... D56: =IF(A56<53,"",IFERROR(((HOUR(B56)*60+MINUTE(B56))/60)*$D$2,"")) | E56: =IFERROR(C56/D56,"") | F56: =IF(A56<53,"",IFERROR(B56/$F$2,"")) | G56: =IF(F56="","",IF(F56>1,"NO",""))

Sheet DASHBOARD
A1: OEE | B1: (Todas)
A3: Etiquetas de fila | B3: Promedio de OEE
A4: 6 | B4: 0.328
A5: 7 | B5: 0.38013333
A6: 8 | B6: 0.17831481
A7: 9 | B7: 0.26048148
A8: 10 | B8: 0.22514815
A9: 11 | B9: 0.2432963
A10: 12 | B10: 0.56007407
A11: 13 | B11: 0.36076296
A12: 17 | B12: 0.30397222
A13: 18 | B13: 0.30457548
A14: 19 | B14: 0.35932593
A15: 20 | B15: 0.51983704
... A25: 30 | B25: 0.55714815
B26: #DIV/0!
A27: Total general | B27: 0.36944771

Sheet Pareto de paradas
A3: Row Labels | B3: Tiempo de no producción | C3: % del total
A4: P | B4: 3.2916667 | C4: 0.64705882
A5: LC | B5: 2.25 | C5: 0.29411765
A6: CF | B6: 0.10416667 | C6: 0.058823529
A7: Grand Total | B7: 5.6458333 | C7: 1
A29: Row Labels | B29: Tiempo de no producción | C29: % del total
A30: P | B30: =B34*C30 -> 2.3289063 | C30: 0.4125 | L30: =0.272/(0.66*0.9989) -> 0.41257504
A31: LC | B31: =B34*C31 -> 2.3455116 | C31: =0.294117647058824*(1+C30) -> 0.41544118
A32: CF | B32: =B34*C32 -> 0.46910233 | C32: =0.0588235294117647*(1+C30) -> 0.083088235 | L32: =0.413*0.662*0.9989 -> 0.27310525
A33: Others | B33: =B34-SUM(B30:B32) -> 0.50231311 | C33: =B33/B34 -> 0.088970588
A34: Grand Total | B34: 5.6458333 | C34: =SUM(C30:C33) -> 1

Sheet Sheet1

Sheet paradas-disp
B1: 0.58333333 | J1: 1800
A2: Día | B2: Hora inicio | C2: Hora fin | D2: Turno | E2: P/LC/CF/CL | F2: Tiempo producción | G2: Tiempo no producción | H2: Semana | I2: Cantidad producida | J2: Cantidad teórica | K2: Rendimiento | L2: Observaciones | M2: tiempo no prod | N2: Comprobar
A3: 45692 | B3: 0.79166667 | C3: 0.88194444 | D3: =+IF(Tabla1[[#This Row],[Hora inicio]]<$B$1,"Mañana","Tarde") -> Tarde | E3: P | F3: =IF(Tabla1[[#This Row],[P/LC/CF/CL]]="P",Tabla1[[#This Row],[Hora fin ]]-Tabla1[[#This Row],[Hora inicio]],"") -> 0.090277778 | G3: =Tabla1[[#This Row],[Hora fin ]]-Tabla1[[#This Row],[Hora inicio]] -> 0.090277778 | H3: =WEEKNUM(Tabla1[[#This Row],[Día]]) -> 6 | I3: 2754 | J3: =IFERROR(((HOUR(Tabla1[[#This Row],[Tiempo producción]])*60+MINUTE(Tabla1[[#This Row],[Tiempo producción]]))/60)*$J$1,"") -> 3900 | K3: =IFERROR(Tabla1[[#This Row],[Cantidad producida]]/Tabla1[[#This Row],[Cantidad teórica]],"") -> 0.70615385 | M3: =IF(Tabla1[[#This Row],[P/LC/CF/CL]]<>"P",Tabla1[[#This Row],[Hora fin ]]-Tabla1[[#This Row],[Hora inicio]],"") | N3: =IF(Tabla1[[#This Row],[Cantidad producida]]>Tabla1[[#This Row],[Cantidad teórica]],"SI","") | P3: =AVERAGEIF(Tabla1[Rendimiento],"<>0",Tabla1[Rendimiento]) -> 0.66224173
A4: 45693 | B4: 0.32986111 | C4: 0.55555556 | D4: =+IF(Tabla1[[#This Row],[Hora inicio]]<$B$1,"Mañana","Tarde") -> Mañana | E4: P | F4: =IF(Tabla1[[#This Row],[P/LC/CF/CL]]="P",Tabla1[[#This Row],[Hora fin ]]-Tabla1[[#This Row],[Hora inicio]],"") -> 0.22569444 | G4: =Tabla1[[#This Row],[Hora fin ]]-Tabla1[[#This Row],[Hora inicio]] -> 0.22569444 | H4: =WEEKNUM(Tabla1[[#This Row],[Día]]) -> 6 | I4: 4446 | J4: =IFERROR(((HOUR(Tabla1[[#This Row],[Tiempo producción]])*60+MINUTE(Tabla1[[#This Row],[Tiempo producción]]))/60)*$J$1,"") -> 9750 | K4: =IFERROR(Tabla1[[#This Row],[Cantidad producida]]/Tabla1[[#This Row],[Cantidad teórica]],"") -> 0.456 | M4: =IF(Tabla1[[#This Row],[P/LC/CF/CL]]<>"P",Tabla1[[#This Row],[Hora fin ]]-Tabla1[[#This Row],[Hora inicio]],"") | N4: =IF(Tabla1[[#This Row],[Cantidad producida]]>Tabla1[[#This Row],[Cantidad teórica]],"SI","")
A5: 45693 | B5: 0.60416667 | C5: 0.85416667 | D5: =+IF(Tabla1[[#This Row],[Hora inicio]]<$B$1,"Mañana","Tarde") -> Tarde | E5: P | F5: =IF(Tabla1[[#This Row],[P/LC/CF/CL]]="P",Tabla1[[#This Row],[Hora fin ]]-Tabla1[[#This Row],[Hora inicio]],"") -> 0.25 | G5: =Tabla1[[#This Row],[Hora fin ]]-Tabla1[[#This Row],[Hora inicio]] -> 0.25 | H5: =WEEKNUM(Tabla1[[#This Row],[Día]]) -> 6 | I5: 8694 | J5: =IFERROR(((HOUR(Tabla1[[#This Row],[Tiempo producción]])*60+MINUTE(Tabla1[[#This Row],[Tiempo producción]]))/60)*$J$1,"") -> 10800 | K5: =IFERROR(Tabla1[[#This Row],[Cantidad producida]]/Tabla1[[#This Row],[Cantidad teórica]],"") -> 0.805 | M5: =IF(Tabla1[[#This Row],[P/LC/CF/CL]]<>"P",Tabla1[[#This Row],[Hora fin ]]-Tabla1[[#This Row],[Hora inicio]],"") | N5: =IF(Tabla1[[#This Row],[Cantidad producida]]>Tabla1[[#This Row],[Cantidad teórica]],"SI","")
A6: 45694 | B6: 0.48958333 | C6: 0.55208333 | D6: =+IF(Tabla1[[#This Row],[Hora inicio]]<$B$1,"Mañana","Tarde") -> Mañana | E6: P | F6: =IF(Tabla1[[#This Row],[P/LC/CF/CL]]="P",Tabla1[[#This Row],[Hora fin ]]-Tabla1[[#This Row],[Hora inicio]],"") -> 0.0625 | G6: =Tabla1[[#This Row],[Hora fin ]]-Tabla1[[#This Row],[Hora inicio]] -> 0.0625 | H6: =WEEKNUM(Tabla1[[#This Row],[Día]]) -> 6 | I6: 1380 | J6: =IFERROR(((HOUR(Tabla1[[#This Row],[Tiempo producción]])*60+MINUTE(Tabla1[[#This Row],[Tiempo producción]]))/60)*$J$1,"") -> 2700 | K6: =IFERROR(Tabla1[[#This Row],[Cantidad producida]]/Tabla1[[#This Row],[Cantidad teórica]],"") -> 0.51111111 | M6: =IF(Tabla1[[#This Row],[P/LC/CF/CL]]<>"P",Tabla1[[#This Row],[Hora fin ]]-Tabla1[[#This Row],[Hora inicio]],"") | N6: =IF(Tabla1[[#This Row],[Cantidad producida]]>Tabla1[[#This Row],[Cantidad teórica]],"SI","")
A7: 45694 | B7: 0.59375 | C7: 0.875 | D7: =+IF(Tabla1[[#This Row],[Hora inicio]]<$B$1,"Mañana","Tarde") -> Tarde | E7: P | F7: =IF(Tabla1[[#This Row],[P/LC/CF/CL]]="P",Tabla1[[#This Row],[Hora fin ]]-Tabla1[[#This Row],[Hora inicio]],"") -> 0.28125 | G7: =Tabla1[[#This Row],[Hora fin ]]-Tabla1[[#This Row],[Hora inicio]] -> 0.28125 | H7: =WEEKNUM(Tabla1[[#This Row],[Día]]) -> 6 | I7: 9558 | J7: =IFERROR(((HOUR(Tabla1[[#This Row],[Tiempo producción]])*60+MINUTE(Tabla1[[#This Row],[Tiempo producción]]))/60)*$J$1,"") -> 12150 | K7: =IFERROR(Tabla1[[#This Row],[Cantidad producida]]/Tabla1[[#This Row],[Cantidad teórica]],"") -> 0.78666667 | M7: =IF(Tabla1[[#This Row],[P/LC/CF/CL]]<>"P",Tabla1[[#This Row],[Hora fin ]]-Tabla1[[#This Row],[Hora inicio]],"") | N7: =IF(Tabla1[[#This Row],[Cantidad producida]]>Tabla1[[#This Row],[Cantidad teórica]],"SI","")
A8: 45695 | B8: 0.25 | C8: 0.5 | D8: =+IF(Tabla1[[#This Row],[Hora inicio]]<$B$1,"Mañana","Tarde") -> Mañana | E8: P | F8: =IF(Tabla1[[#This Row],[P/LC/CF/CL]]="P",Tabla1[[#This Row],[Hora fin ]]-Tabla1[[#This Row],[Hora inicio]],"") -> 0.25 | G8: =Tabla1[[#This Row],[Hora fin ]]-Tabla1[[#This Row],[Hora inicio]] -> 0.25 | H8: =WEEKNUM(Tabla1[[#This Row],[Día]]) -> 6 | I8: 6144 | J8: =IFERROR(((HOUR(Tabla1[[#This Row],[Tiempo producción]])*60+MINUTE(Tabla1[[#This Row],[Tiempo producción]]))/60)*$J$1,"") -> 10800 | K8: =IFERROR(Tabla1[[#This Row],[Cantidad producida]]/Tabla1[[#This Row],[Cantidad teórica]],"") -> 0.56888889 | M8: =IF(Tabla1[[#This Row],[P/LC/CF/CL]]<>"P",Tabla1[[#This Row],[Hora fin ]]-Tabla1[[#This Row],[Hora inicio]],"") | N8: =IF(Tabla1[[#This Row],[Cantidad producida]]>Tabla1[[#This Row],[Cantidad teórica]],"SI","")
A9: 45695 | B9: 0.6875 | C9: 0.78472222 | D9: =+IF(Tabla1[[#This Row],[Hora inicio]]<$B$1,"Mañana","Tarde") -> Tarde | E9: P | F9: =IF(Tabla1[[#This Row],[P/LC/CF/CL]]="P",Tabla1[[#This Row],[Hora fin ]]-Tabla1[[#This Row],[Hora inicio]],"") -> 0.097222222 | G9: =Tabla1[[#This Row],[Hora fin ]]-Tabla1[[#This Row],[Hora inicio]] -> 0.097222222 | H9: =WEEKNUM(Tabla1[[#This Row],[Día]]) -> 6 | I9: 2448 | J9: =IFERROR(((HOUR(Tabla1[[#This Row],[Tiempo producción]])*60+MINUTE(Tabla1[[#This Row],[Tiempo producción]]))/60)*$J$1,"") -> 4200 | K9: =IFERROR(Tabla1[[#This Row],[Cantidad producida]]/Tabla1[[#This Row],[Cantidad teórica]],"") -> 0.58285714 | M9: =IF(Tabla1[[#This Row],[P/LC/CF/CL]]<>"P",Tabla1[[#This Row],[Hora fin ]]-Tabla1[[#This Row],[Hora inicio]],"") | N9: =IF(Tabla1[[#This Row],[Cantidad producida]]>Tabla1[[#This Row],[Cantidad teórica]],"SI","")
A10: 45698 | B10: 0.86111111 | C10: 0.91666667 | D10: =+IF(Tabla1[[#This Row],[Hora inicio]]<$B$1,"Mañana","Tarde") -> Tarde | E10: P | F10: =IF(Tabla1[[#This Row],[P/LC/CF/CL]]="P",Tabla1[[#This Row],[Hora fin ]]-Tabla1[[#This Row],[Hora inicio]],"") -> 0.055555556 | G10: =Tabla1[[#This Row],[Hora fin ]]-Tabla1[[#This Row],[Hora inicio]] -> 0.055555556 | H10: =WEEKNUM(Tabla1[[#This Row],[Día]]) -> 7 | I10: 384 | J10: =IFERROR(((HOUR(Tabla1[[#This Row],[Tiempo producción]])*60+MINUTE(Tabla1[[#This Row],[Tiempo producción]]))/60)*$J$1,"") -> 2400 | K10: =IFERROR(Tabla1[[#This Row],[Cantidad producida]]/Tabla1[[#This Row],[Cantidad teórica]],"") -> 0.16 | M10: =IF(Tabla1[[#This Row],[P/LC/CF/CL]]<>"P",Tabla1[[#This Row],[Hora fin ]]-Tabla1[[#This Row],[Hora inicio]],"") | N10: =IF(Tabla1[[#This Row],[Cantidad producida]]>Tabla1[[#This Row],[Cantidad teórica]],"SI","")
A11: 45699 | B11: 0.30208333 | C11: 0.58333333 | D11: =+IF(Tabla1[[#This Row],[Hora inicio]]<$B$1,"Mañana","Tarde") -> Mañana | E11: P | F11: =IF(Tabla1[[#This Row],[P/LC/CF/CL]]="P",Tabla1[[#This Row],[Hora fin ]]-Tabla1[[#This Row],[Hora inicio]],"") -> 0.28125 | G11: =Tabla1[[#This Row],[Hora fin ]]-Tabla1[[#This Row],[Hora inicio]] -> 0.28125 | H11: =WEEKNUM(Tabla1[[#This Row],[Día]]) -> 7 | I11: 5820 | J11: =IFERROR(((HOUR(Tabla1[[#This Row],[Tiempo producción]])*60+MINUTE(Tabla1[[#This Row],[Tiempo producción]]))/60)*$J$1,"") -> 12150 | K11: =IFERROR(Tabla1[[#This Row],[Cantidad producida]]/Tabla1[[#This Row],[Cantidad teórica]],"") -> 0.47901235 | M11: =IF(Tabla1[[#This Row],[P/LC/CF/CL]]<>"P",Tabla1[[#This Row],[Hora fin ]]-Tabla1[[#This Row],[Hora inicio]],"") | N11: =IF(Tabla1[[#This Row],[Cantidad producida]]>Tabla1[[#This Row],[Cantidad teórica]],"SI","")
A12: 45700 | B12: 0.25694444 | C12: 0.57986111 | D12: =+IF(Tabla1[[#This Row],[Hora inicio]]<$B$1,"Mañana","Tarde") -> Mañana | E12: P | F12: =IF(Tabla1[[#This Row],[P/LC/CF/CL]]="P",Tabla1[[#This Row],[Hora fin ]]-Tabla1[[#This Row],[Hora inicio]],"") -> 0.32291667 | G12: =Tabla1[[#This Row],[Hora fin ]]-Tabla1[[#This Row],[Hora inicio]] -> 0.32291667 | H12: =WEEKNUM(Tabla1[[#This Row],[Día]]) -> 7 | I12: 6840 | J12: =IFERROR(((HOUR(Tabla1[[#This Row],[Tiempo producción]])*60+MINUTE(Tabla1[[#This Row],[Tiempo producción]]))/60)*$J$1,"") -> 13950 | K12: =IFERROR(Tabla1[[#This Row],[Cantidad producida]]/Tabla1[[#This Row],[Cantidad teórica]],"") -> 0.49032258 | M12: =IF(Tabla1[[#This Row],[P/LC/CF/CL]]<>"P",Tabla1[[#This Row],[Hora fin ]]-Tabla1[[#This Row],[Hora inicio]],"") | N12: =IF(Tabla1[[#This Row],[Cantidad producida]]>Tabla1[[#This Row],[Cantidad teórica]],"SI","")
A13: 45700 | B13: 0.60069444 | C13: 0.67708333 | D13: =+IF(Tabla1[[#This Row],[Hora inicio]]<$B$1,"Mañana","Tarde") -> Tarde | E13: P | F13: =IF(Tabla1[[#This Row],[P/LC/CF/CL]]="P",Tabla1[[#This Row],[Hora fin ]]-Tabla1[[#This Row],[Hora inicio]],"") -> 0.076388889 | G13: =Tabla1[[#This Row],[Hora fin ]]-Tabla1[[#This Row],[Hora inicio]] -> 0.076388889 | H13: =WEEKNUM(Tabla1[[#This Row],[Día]]) -> 7 | I13: 2052 | J13: =IFERROR(((HOUR(Tabla1[[#This Row],[Tiempo producción]])*60+MINUTE(Tabla1[[#This Row],[Tiempo producción]]))/60)*$J$1,"") -> 3300 | K13: =IFERROR(Tabla1[[#This Row],[Cantidad producida]]/Tabla1[[#This Row],[Cantidad teórica]],"") -> 0.62181818 | M13: =IF(Tabla1[[#This Row],[P/LC/CF/CL]]<>"P",Tabla1[[#This Row],[Hora fin ]]-Tabla1[[#This Row],[Hora inicio]],"") | N13: =IF(Tabla1[[#This Row],[Cantidad producida]]>Tabla1[[#This Row],[Cantidad teórica]],"SI","")
A14: 45700 | B14: 0.69791667 | C14: 0.91666667 | D14: =+IF(Tabla1[[#This Row],[Hora inicio]]<$B$1,"Mañana","Tarde") -> Tarde | E14: P | F14: =IF(Tabla1[[#This Row],[P/LC/CF/CL]]="P",Tabla1[[#This Row],[Hora fin ]]-Tabla1[[#This Row],[Hora inicio]],"") -> 0.21875 | G14: =Tabla1[[#This Row],[Hora fin ]]-Tabla1[[#This Row],[Hora inicio]] -> 0.21875 | H14: =WEEKNUM(Tabla1[[#This Row],[Día]]) -> 7 | I14: 5820 | J14: =IFERROR(((HOUR(Tabla1[[#This Row],[Tiempo producción]])*60+MINUTE(Tabla1[[#This Row],[Tiempo producción]]))/60)*$J$1,"") -> 9450 | K14: =IFERROR(Tabla1[[#This Row],[Cantidad producida]]/Tabla1[[#This Row],[Cantidad teórica]],"") -> 0.61587302 | M14: =IF(Tabla1[[#This Row],[P/LC/CF/CL]]<>"P",Tabla1[[#This Row],[Hora fin ]]-Tabla1[[#This Row],[Hora inicio]],"") | N14: =IF(Tabla1[[#This Row],[Cantidad producida]]>Tabla1[[#This Row],[Cantidad teórica]],"SI","")
A15: 45701 | B15: 0.26041667 | C15: 0.55208333 | D15: =+IF(Tabla1[[#This Row],[Hora inicio]]<$B$1,"Mañana","Tarde") -> Mañana | E15: P | F15: =IF(Tabla1[[#This Row],[P/LC/CF/CL]]="P",Tabla1[[#This Row],[Hora fin ]]-Tabla1[[#This Row],[Hora inicio]],"") -> 0.29166667 | G15: =Tabla1[[#This Row],[Hora fin ]]-Tabla1[[#This Row],[Hora inicio]] -> 0.29166667 | H15: =WEEKNUM(Tabla1[[#This Row],[Día]]) -> 7 | I15: 9756 | J15: =IFERROR(((HOUR(Tabla1[[#This Row],[Tiempo producción]])*60+MINUTE(Tabla1[[#This Row],[Tiempo producción]]))/60)*$J$1,"") -> 12600 | K15: =IFERROR(Tabla1[[#This Row],[Cantidad producida]]/Tabla1[[#This Row],[Cantidad teórica]],"") -> 0.77428571 | M15: =IF(Tabla1[[#This Row],[P/LC/CF/CL]]<>"P",Tabla1[[#This Row],[Hora fin ]]-Tabla1[[#This Row],[Hora inicio]],"") | N15: =IF(Tabla1[[#This Row],[Cantidad producida]]>Tabla1[[#This Row],[Cantidad teórica]],"SI","")
... A52: 45729 | B52: 0.59027778 | C52: 0.89583333 | D52: =+IF(Tabla1[[#This Row],[Hora inicio]]<$B$1,"Mañana","Tarde") -> Tarde | E52: P | F52: =IF(Tabla1[[#This Row],[P/LC/CF/CL]]="P",Tabla1[[#This Row],[Hora fin ]]-Tabla1[[#This Row],[Hora inicio]],"") -> 0.30555556 | G52: =Tabla1[[#This Row],[Hora fin ]]-Tabla1[[#This Row],[Hora inicio]] -> 0.30555556 | H52: =WEEKNUM(Tabla1[[#This Row],[Día]]) -> 11 | I52: 10182 | J52: =IFERROR(((HOUR(Tabla1[[#This Row],[Tiempo producción]])*60+MINUTE(Tabla1[[#This Row],[Tiempo producción]]))/60)*$J$1,"") -> 13200 | K52: =IFERROR(Tabla1[[#This Row],[Cantidad producida]]/Tabla1[[#This Row],[Cantidad teórica]],"") -> 0.77136364 | M52: =IF(Tabla1[[#This Row],[P/LC/CF/CL]]<>"P",Tabla1[[#This Row],[Hora fin ]]-Tabla1[[#This Row],[Hora inicio]],"") | N52: =IF(Tabla1[[#This Row],[Cantidad producida]]>Tabla1[[#This Row],[Cantidad teórica]],"SI","")
A53: 45733 | B53: 0.28125 | C53: 0.57291667 | D53: =+IF(Tabla1[[#This Row],[Hora inicio]]<$B$1,"Mañana","Tarde") -> Mañana | E53: P | F53: =IF(Tabla1[[#This Row],[P/LC/CF/CL]]="P",Tabla1[[#This Row],[Hora fin ]]-Tabla1[[#This Row],[Hora inicio]],"") -> 0.29166667 | G53: =Tabla1[[#This Row],[Hora fin ]]-Tabla1[[#This Row],[Hora inicio]] -> 0.29166667 | H53: =WEEKNUM(Tabla1[[#This Row],[Día]]) -> 12 | J53: =IFERROR(((HOUR(Tabla1[[#This Row],[Tiempo producción]])*60+MINUTE(Tabla1[[#This Row],[Tiempo producción]]))/60)*$J$1,"") -> 12600 | K53: =IFERROR(Tabla1[[#This Row],[Cantidad producida]]/Tabla1[[#This Row],[Cantidad teórica]],"") -> 0 | M53: =IF(Tabla1[[#This Row],[P/LC/CF/CL]]<>"P",Tabla1[[#This Row],[Hora fin ]]-Tabla1[[#This Row],[Hora inicio]],"") | N53: =IF(Tabla1[[#This Row],[Cantidad producida]]>Tabla1[[#This Row],[Cantidad teórica]],"SI","")
A54: 45733 | B54: 0.59375 | C54: 0.72222222 | D54: =+IF(Tabla1[[#This Row],[Hora inicio]]<$B$1,"Mañana","Tarde") -> Tarde | E54: P | F54: =IF(Tabla1[[#This Row],[P/LC/CF/CL]]="P",Tabla1[[#This Row],[Hora fin ]]-Tabla1[[#This Row],[Hora inicio]],"") -> 0.12847222 | G54: =Tabla1[[#This Row],[Hora fin ]]-Tabla1[[#This Row],[Hora inicio]] -> 0.12847222 | H54: =WEEKNUM(Tabla1[[#This Row],[Día]]) -> 12 | J54: =IFERROR(((HOUR(Tabla1[[#This Row],[Tiempo producción]])*60+MINUTE(Tabla1[[#This Row],[Tiempo producción]]))/60)*$J$1,"") -> 5550 | K54: =IFERROR(Tabla1[[#This Row],[Cantidad producida]]/Tabla1[[#This Row],[Cantidad teórica]],"") -> 0 | M54: =IF(Tabla1[[#This Row],[P/LC/CF/CL]]<>"P",Tabla1[[#This Row],[Hora fin ]]-Tabla1[[#This Row],[Hora inicio]],"") | N54: =IF(Tabla1[[#This Row],[Cantidad producida]]>Tabla1[[#This Row],[Cantidad teórica]],"SI","")
A55: 45733 | B55: 0.72222222 | C55: 0.72916667 | D55: =+IF(Tabla1[[#This Row],[Hora inicio]]<$B$1,"Mañana","Tarde") -> Tarde | E55: CL | F55: =IF(Tabla1[[#This Row],[P/LC/CF/CL]]="P",Tabla1[[#This Row],[Hora fin ]]-Tabla1[[#This Row],[Hora inicio]],"") | G55: =Tabla1[[#This Row],[Hora fin ]]-Tabla1[[#This Row],[Hora inicio]] -> 0.0069444444 | H55: =WEEKNUM(Tabla1[[#This Row],[Día]]) -> 12 | J55: =IFERROR(((HOUR(Tabla1[[#This Row],[Tiempo producción]])*60+MINUTE(Tabla1[[#This Row],[Tiempo producción]]))/60)*$J$1,"") | K55: =IFERROR(Tabla1[[#This Row],[Cantidad producida]]/Tabla1[[#This Row],[Cantidad teórica]],"") | M55: =IF(Tabla1[[#This Row],[P/LC/CF/CL]]<>"P",Tabla1[[#This Row],[Hora fin ]]-Tabla1[[#This Row],[Hora inicio]],"") -> 0.0069444444 | N55: =IF(Tabla1[[#This Row],[Cantidad producida]]>Tabla1[[#This Row],[Cantidad teórica]],"SI","")
A56: 45733 | B56: 0.72916667 | C56: 0.91666667 | D56: =+IF(Tabla1[[#This Row],[Hora inicio]]<$B$1,"Mañana","Tarde") -> Tarde | E56: P | F56: =IF(Tabla1[[#This Row],[P/LC/CF/CL]]="P",Tabla1[[#This Row],[Hora fin ]]-Tabla1[[#This Row],[Hora inicio]],"") -> 0.1875 | G56: =Tabla1[[#This Row],[Hora fin ]]-Tabla1[[#This Row],[Hora inicio]] -> 0.1875 | H56: =WEEKNUM(Tabla1[[#This Row],[Día]]) -> 12 | J56: =IFERROR(((HOUR(Tabla1[[#This Row],[Tiempo producción]])*60+MINUTE(Tabla1[[#This Row],[Tiempo producción]]))/60)*$J$1,"") -> 8100 | K56: =IFERROR(Tabla1[[#This Row],[Cantidad producida]]/Tabla1[[#This Row],[Cantidad teórica]],"") -> 0 | M56: =IF(Tabla1[[#This Row],[P/LC/CF/CL]]<>"P",Tabla1[[#This Row],[Hora fin ]]-Tabla1[[#This Row],[Hora inicio]],"") | N56: =IF(Tabla1[[#This Row],[Cantidad producida]]>Tabla1[[#This Row],[Cantidad teórica]],"SI","")
A57: 45734 | B57: 0.26041667 | C57: 0.39583333 | D57: =+IF(Tabla1[[#This Row],[Hora inicio]]<$B$1,"Mañana","Tarde") -> Mañana | E57: P | F57: =IF(Tabla1[[#This Row],[P/LC/CF/CL]]="P",Tabla1[[#This Row],[Hora fin ]]-Tabla1[[#This Row],[Hora inicio]],"") -> 0.13541667 | G57: =Tabla1[[#This Row],[Hora fin ]]-Tabla1[[#This Row],[Hora inicio]] -> 0.13541667 | H57: =WEEKNUM(Tabla1[[#This Row],[Día]]) -> 12 | J57: =IFERROR(((HOUR(Tabla1[[#This Row],[Tiempo producción]])*60+MINUTE(Tabla1[[#This Row],[Tiempo producción]]))/60)*$J$1,"") -> 5850 | K57: =IFERROR(Tabla1[[#This Row],[Cantidad producida]]/Tabla1[[#This Row],[Cantidad teórica]],"") -> 0 | M57: =IF(Tabla1[[#This Row],[P/LC/CF/CL]]<>"P",Tabla1[[#This Row],[Hora fin ]]-Tabla1[[#This Row],[Hora inicio]],"") | N57: =IF(Tabla1[[#This Row],[Cantidad producida]]>Tabla1[[#This Row],[Cantidad teórica]],"SI","")
A58: 45734 | B58: 0.39583333 | C58: 0.41666667 | D58: =+IF(Tabla1[[#This Row],[Hora inicio]]<$B$1,"Mañana","Tarde") -> Mañana | E58: CL | F58: =IF(Tabla1[[#This Row],[P/LC/CF/CL]]="P",Tabla1[[#This Row],[Hora fin ]]-Tabla1[[#This Row],[Hora inicio]],"") | G58: =Tabla1[[#This Row],[Hora fin ]]-Tabla1[[#This Row],[Hora inicio]] -> 0.020833333 | H58: =WEEKNUM(Tabla1[[#This Row],[Día]]) -> 12 | J58: =IFERROR(((HOUR(Tabla1[[#This Row],[Tiempo producción]])*60+MINUTE(Tabla1[[#This Row],[Tiempo producción]]))/60)*$J$1,"") | K58: =IFERROR(Tabla1[[#This Row],[Cantidad producida]]/Tabla1[[#This Row],[Cantidad teórica]],"") | M58: =IF(Tabla1[[#This Row],[P/LC/CF/CL]]<>"P",Tabla1[[#This Row],[Hora fin ]]-Tabla1[[#This Row],[Hora inicio]],"") -> 0.020833333 | N58: =IF(Tabla1[[#This Row],[Cantidad producida]]>Tabla1[[#This Row],[Cantidad teórica]],"SI","")
A59: 45734 | B59: 0.41666667 | C59: 0.58333333 | D59: =+IF(Tabla1[[#This Row],[Hora inicio]]<$B$1,"Mañana","Tarde") -> Mañana | E59: P | F59: =IF(Tabla1[[#This Row],[P/LC/CF/CL]]="P",Tabla1[[#This Row],[Hora fin ]]-Tabla1[[#This Row],[Hora inicio]],"") -> 0.16666667 | G59: =Tabla1[[#This Row],[Hora fin ]]-Tabla1[[#This Row],[Hora inicio]] -> 0.16666667 | H59: =WEEKNUM(Tabla1[[#This Row],[Día]]) -> 12 | J59: =IFERROR(((HOUR(Tabla1[[#This Row],[Tiempo producción]])*60+MINUTE(Tabla1[[#This Row],[Tiempo producción]]))/60)*$J$1,"") -> 7200 | K59: =IFERROR(Tabla1[[#This Row],[Cantidad producida]]/Tabla1[[#This Row],[Cantidad teórica]],"") -> 0 | M59: =IF(Tabla1[[#This Row],[P/LC/CF/CL]]<>"P",Tabla1[[#This Row],[Hora fin ]]-Tabla1[[#This Row],[Hora inicio]],"") | N59: =IF(Tabla1[[#This Row],[Cantidad producida]]>Tabla1[[#This Row],[Cantidad teórica]],"SI","")
A60: 45734 | B60: 0.59375 | C60: 0.70138889 | D60: =+IF(Tabla1[[#This Row],[Hora inicio]]<$B$1,"Mañana","Tarde") -> Tarde | E60: P | F60: =IF(Tabla1[[#This Row],[P/LC/CF/CL]]="P",Tabla1[[#This Row],[Hora fin ]]-Tabla1[[#This Row],[Hora inicio]],"") -> 0.10763889 | G60: =Tabla1[[#This Row],[Hora fin ]]-Tabla1[[#This Row],[Hora inicio]] -> 0.10763889 | H60: =WEEKNUM(Tabla1[[#This Row],[Día]]) -> 12 | J60: =IFERROR(((HOUR(Tabla1[[#This Row],[Tiempo producción]])*60+MINUTE(Tabla1[[#This Row],[Tiempo producción]]))/60)*$J$1,"") -> 4650 | K60: =IFERROR(Tabla1[[#This Row],[Cantidad producida]]/Tabla1[[#This Row],[Cantidad teórica]],"") -> 0 | M60: =IF(Tabla1[[#This Row],[P/LC/CF/CL]]<>"P",Tabla1[[#This Row],[Hora fin ]]-Tabla1[[#This Row],[Hora inicio]],"") | N60: =IF(Tabla1[[#This Row],[Cantidad producida]]>Tabla1[[#This Row],[Cantidad teórica]],"SI","")
A61: 45734 | B61: 0.70138889 | C61: 0.74305556 | D61: =+IF(Tabla1[[#This Row],[Hora inicio]]<$B$1,"Mañana","Tarde") -> Tarde | E61: CL | F61: =IF(Tabla1[[#This Row],[P/LC/CF/CL]]="P",Tabla1[[#This Row],[Hora fin ]]-Tabla1[[#This Row],[Hora inicio]],"") | G61: =Tabla1[[#This Row],[Hora fin ]]-Tabla1[[#This Row],[Hora inicio]] -> 0.041666667 | H61: =WEEKNUM(Tabla1[[#This Row],[Día]]) -> 12 | J61: =IFERROR(((HOUR(Tabla1[[#This Row],[Tiempo producción]])*60+MINUTE(Tabla1[[#This Row],[Tiempo producción]]))/60)*$J$1,"") | K61: =IFERROR(Tabla1[[#This Row],[Cantidad producida]]/Tabla1[[#This Row],[Cantidad teórica]],"") | M61: =IF(Tabla1[[#This Row],[P/LC/CF/CL]]<>"P",Tabla1[[#This Row],[Hora fin ]]-Tabla1[[#This Row],[Hora inicio]],"") -> 0.041666667 | N61: =IF(Tabla1[[#This Row],[Cantidad producida]]>Tabla1[[#This Row],[Cantidad teórica]],"SI","")
A62: 45734 | B62: 0.74305556 | C62: 0.91666667 | D62: =+IF(Tabla1[[#This Row],[Hora inicio]]<$B$1,"Mañana","Tarde") -> Tarde | E62: P | F62: =IF(Tabla1[[#This Row],[P/LC/CF/CL]]="P",Tabla1[[#This Row],[Hora fin ]]-Tabla1[[#This Row],[Hora inicio]],"") -> 0.17361111 | G62: =Tabla1[[#This Row],[Hora fin ]]-Tabla1[[#This Row],[Hora inicio]] -> 0.17361111 | H62: =WEEKNUM(Tabla1[[#This Row],[Día]]) -> 12 | J62: =IFERROR(((HOUR(Tabla1[[#This Row],[Tiempo producción]])*60+MINUTE(Tabla1[[#This Row],[Tiempo producción]]))/60)*$J$1,"") -> 7500 | K62: =IFERROR(Tabla1[[#This Row],[Cantidad producida]]/Tabla1[[#This Row],[Cantidad teórica]],"") -> 0 | M62: =IF(Tabla1[[#This Row],[P/LC/CF/CL]]<>"P",Tabla1[[#This Row],[Hora fin ]]-Tabla1[[#This Row],[Hora inicio]],"") | N62: =IF(Tabla1[[#This Row],[Cantidad producida]]>Tabla1[[#This Row],[Cantidad teórica]],"SI","")
A63: 45735 | B63: 0.26388889 | C63: 0.5625 | D63: =+IF(Tabla1[[#This Row],[Hora inicio]]<$B$1,"Mañana","Tarde") -> Mañana | E63: P | F63: =IF(Tabla1[[#This Row],[P/LC/CF/CL]]="P",Tabla1[[#This Row],[Hora fin ]]-Tabla1[[#This Row],[Hora inicio]],"") -> 0.29861111 | G63: =Tabla1[[#This Row],[Hora fin ]]-Tabla1[[#This Row],[Hora inicio]] -> 0.29861111 | H63: =WEEKNUM(Tabla1[[#This Row],[Día]]) -> 12 | J63: =IFERROR(((HOUR(Tabla1[[#This Row],[Tiempo producción]])*60+MINUTE(Tabla1[[#This Row],[Tiempo producción]]))/60)*$J$1,"") -> 12900 | K63: =IFERROR(Tabla1[[#This Row],[Cantidad producida]]/Tabla1[[#This Row],[Cantidad teórica]],"") -> 0 | M63: =IF(Tabla1[[#This Row],[P/LC/CF/CL]]<>"P",Tabla1[[#This Row],[Hora fin ]]-Tabla1[[#This Row],[Hora inicio]],"") | N63: =IF(Tabla1[[#This Row],[Cantidad producida]]>Tabla1[[#This Row],[Cantidad teórica]],"SI","")
A64: 45735 | B64: 0.59375 | C64: 0.80208333 | D64: =+IF(Tabla1[[#This Row],[Hora inicio]]<$B$1,"Mañana","Tarde") -> Tarde | E64: P | F64: =IF(Tabla1[[#This Row],[P/LC/CF/CL]]="P",Tabla1[[#This Row],[Hora fin ]]-Tabla1[[#This Row],[Hora inicio]],"") -> 0.20833333 | G64: =Tabla1[[#This Row],[Hora fin ]]-Tabla1[[#This Row],[Hora inicio]] -> 0.20833333 | H64: =WEEKNUM(Tabla1[[#This Row],[Día]]) -> 12 | J64: =IFERROR(((HOUR(Tabla1[[#This Row],[Tiempo producción]])*60+MINUTE(Tabla1[[#This Row],[Tiempo producción]]))/60)*$J$1,"") -> 9000 | K64: =IFERROR(Tabla1[[#This Row],[Cantidad producida]]/Tabla1[[#This Row],[Cantidad teórica]],"") -> 0 | M64: =IF(Tabla1[[#This Row],[P/LC/CF/CL]]<>"P",Tabla1[[#This Row],[Hora fin ]]-Tabla1[[#This Row],[Hora inicio]],"") | N64: =IF(Tabla1[[#This Row],[Cantidad producida]]>Tabla1[[#This Row],[Cantidad teórica]],"SI","")
... A92: 45769 | B92: 0.25 | C92: 0.58333333 | D92: =+IF(Tabla1[[#This Row],[Hora inicio]]<$B$1,"Mañana","Tarde") -> Mañana | E92: LC | F92: =IF(Tabla1[[#This Row],[P/LC/CF/CL]]="P",Tabla1[[#This Row],[Hora fin ]]-Tabla1[[#This Row],[Hora inicio]],"") | G92: =Tabla1[[#This Row],[Hora fin ]]-Tabla1[[#This Row],[Hora inicio]] -> 0.33333333 | H92: =WEEKNUM(Tabla1[[#This Row],[Día]]) -> 17 | J92: =IFERROR(((HOUR(Tabla1[[#This Row],[Tiempo producción]])*60+MINUTE(Tabla1[[#This Row],[Tiempo producción]]))/60)*$J$1,"") | K92: =IFERROR(Tabla1[[#This Row],[Cantidad producida]]/Tabla1[[#This Row],[Cantidad teórica]],"") | M92: =IF(Tabla1[[#This Row],[P/LC/CF/CL]]<>"P",Tabla1[[#This Row],[Hora fin ]]-Tabla1[[#This Row],[Hora inicio]],"") -> 0.33333333 | N92: =IF(Tabla1[[#This Row],[Cantidad producida]]>Tabla1[[#This Row],[Cantidad teórica]],"SI","")
A93: 45769 | B93: 0.58333333 | C93: 0.91666667 | D93: =+IF(Tabla1[[#This Row],[Hora inicio]]<$B$1,"Mañana","Tarde") -> Tarde | E93: P | F93: =IF(Tabla1[[#This Row],[P/LC/CF/CL]]="P",Tabla1[[#This Row],[Hora fin ]]-Tabla1[[#This Row],[Hora inicio]],"") -> 0.33333333 | G93: =Tabla1[[#This Row],[Hora fin ]]-Tabla1[[#This Row],[Hora inicio]] -> 0.33333333 | H93: =WEEKNUM(Tabla1[[#This Row],[Día]]) -> 17 | I93: 1 | J93: =IFERROR(((HOUR(Tabla1[[#This Row],[Tiempo producción]])*60+MINUTE(Tabla1[[#This Row],[Tiempo producción]]))/60)*$J$1,"") -> 14400 | K93: =IFERROR(Tabla1[[#This Row],[Cantidad producida]]/Tabla1[[#This Row],[Cantidad teórica]],"") -> 6.9444444e-05 | M93: =IF(Tabla1[[#This Row],[P/LC/CF/CL]]<>"P",Tabla1[[#This Row],[Hora fin ]]-Tabla1[[#This Row],[Hora inicio]],"") | N93: =IF(Tabla1[[#This Row],[Cantidad producida]]>Tabla1[[#This Row],[Cantidad teórica]],"SI","")
A94: 45770 | B94: 0.25 | C94: 0.91666667 | D94: =+IF(Tabla1[[#This Row],[Hora inicio]]<$B$1,"Mañana","Tarde") -> Mañana | E94: P | F94: =IF(Tabla1[[#This Row],[P/LC/CF/CL]]="P",Tabla1[[#This Row],[Hora fin ]]-Tabla1[[#This Row],[Hora inicio]],"") -> 0.66666667 | G94: =Tabla1[[#This Row],[Hora fin ]]-Tabla1[[#This Row],[Hora inicio]] -> 0.66666667 | H94: =WEEKNUM(Tabla1[[#This Row],[Día]]) -> 17 | J94: =IFERROR(((HOUR(Tabla1[[#This Row],[Tiempo producción]])*60+MINUTE(Tabla1[[#This Row],[Tiempo producción]]))/60)*$J$1,"") -> 28800 | K94: =IFERROR(Tabla1[[#This Row],[Cantidad producida]]/Tabla1[[#This Row],[Cantidad teórica]],"") -> 0 | M94: =IF(Tabla1[[#This Row],[P/LC/CF/CL]]<>"P",Tabla1[[#This Row],[Hora fin ]]-Tabla1[[#This Row],[Hora inicio]],"") | N94: =IF(Tabla1[[#This Row],[Cantidad producida]]>Tabla1[[#This Row],[Cantidad teórica]],"SI","")
A95: 45771 | B95: 0.25 | C95: 0.91666667 | D95: =+IF(Tabla1[[#This Row],[Hora inicio]]<$B$1,"Mañana","Tarde") -> Mañana | E95: P | F95: =IF(Tabla1[[#This Row],[P/LC/CF/CL]]="P",Tabla1[[#This Row],[Hora fin ]]-Tabla1[[#This Row],[Hora inicio]],"") -> 0.66666667 | G95: =Tabla1[[#This Row],[Hora fin ]]-Tabla1[[#This Row],[Hora inicio]] -> 0.66666667 | H95: =WEEKNUM(Tabla1[[#This Row],[Día]]) -> 17 | J95: =IFERROR(((HOUR(Tabla1[[#This Row],[Tiempo producción]])*60+MINUTE(Tabla1[[#This Row],[Tiempo producción]]))/60)*$J$1,"") -> 28800 | K95: =IFERROR(Tabla1[[#This Row],[Cantidad producida]]/Tabla1[[#This Row],[Cantidad teórica]],"") -> 0 | M95: =IF(Tabla1[[#This Row],[P/LC/CF/CL]]<>"P",Tabla1[[#This Row],[Hora fin ]]-Tabla1[[#This Row],[Hora inicio]],"") | N95: =IF(Tabla1[[#This Row],[Cantidad producida]]>Tabla1[[#This Row],[Cantidad teórica]],"SI","")
A96: 45772 | B96: 0.25 | C96: 0.58333333 | D96: =+IF(Tabla1[[#This Row],[Hora inicio]]<$B$1,"Mañana","Tarde") -> Mañana | E96: P | F96: =IF(Tabla1[[#This Row],[P/LC/CF/CL]]="P",Tabla1[[#This Row],[Hora fin ]]-Tabla1[[#This Row],[Hora inicio]],"") -> 0.33333333 | G96: =Tabla1[[#This Row],[Hora fin ]]-Tabla1[[#This Row],[Hora inicio]] -> 0.33333333 | H96: =WEEKNUM(Tabla1[[#This Row],[Día]]) -> 17 | J96: =IFERROR(((HOUR(Tabla1[[#This Row],[Tiempo producción]])*60+MINUTE(Tabla1[[#This Row],[Tiempo producción]]))/60)*$J$1,"") -> 14400 | K96: =IFERROR(Tabla1[[#This Row],[Cantidad producida]]/Tabla1[[#This Row],[Cantidad teórica]],"") -> 0 | M96: =IF(Tabla1[[#This Row],[P/LC/CF/CL]]<>"P",Tabla1[[#This Row],[Hora fin ]]-Tabla1[[#This Row],[Hora inicio]],"") | N96: =IF(Tabla1[[#This Row],[Cantidad producida]]>Tabla1[[#This Row],[Cantidad teórica]],"SI","")
A97: 45772 | B97: 0.71875 | C97: 0.82291667 | D97: =+IF(Tabla1[[#This Row],[Hora inicio]]<$B$1,"Mañana","Tarde") -> Tarde | E97: CF | F97: =IF(Tabla1[[#This Row],[P/LC/CF/CL]]="P",Tabla1[[#This Row],[Hora fin ]]-Tabla1[[#This Row],[Hora inicio]],"") | G97: =Tabla1[[#This Row],[Hora fin ]]-Tabla1[[#This Row],[Hora inicio]] -> 0.10416667 | H97: =WEEKNUM(Tabla1[[#This Row],[Día]]) -> 17 | J97: =IFERROR(((HOUR(Tabla1[[#This Row],[Tiempo producción]])*60+MINUTE(Tabla1[[#This Row],[Tiempo producción]]))/60)*$J$1,"") | K97: =IFERROR(Tabla1[[#This Row],[Cantidad producida]]/Tabla1[[#This Row],[Cantidad teórica]],"") | M97: =IF(Tabla1[[#This Row],[P/LC/CF/CL]]<>"P",Tabla1[[#This Row],[Hora fin ]]-Tabla1[[#This Row],[Hora inicio]],"") -> 0.10416667 | N97: =IF(Tabla1[[#This Row],[Cantidad producida]]>Tabla1[[#This Row],[Cantidad teórica]],"SI","")
A98: 45772 | B98: 0.83333333 | C98: 0.90277778 | D98: =+IF(Tabla1[[#This Row],[Hora inicio]]<$B$1,"Mañana","Tarde") -> Tarde | E98: P | F98: =IF(Tabla1[[#This Row],[P/LC/CF/CL]]="P",Tabla1[[#This Row],[Hora fin ]]-Tabla1[[#This Row],[Hora inicio]],"") -> 0.069444444 | G98: =Tabla1[[#This Row],[Hora fin ]]-Tabla1[[#This Row],[Hora inicio]] -> 0.069444444 | H98: =WEEKNUM(Tabla1[[#This Row],[Día]]) -> 17 | J98: =IFERROR(((HOUR(Tabla1[[#This Row],[Tiempo producción]])*60+MINUTE(Tabla1[[#This Row],[Tiempo producción]]))/60)*$J$1,"") -> 3000 | K98: =IFERROR(Tabla1[[#This Row],[Cantidad producida]]/Tabla1[[#This Row],[Cantidad teórica]],"") -> 0 | M98: =IF(Tabla1[[#This Row],[P/LC/CF/CL]]<>"P",Tabla1[[#This Row],[Hora fin ]]-Tabla1[[#This Row],[Hora inicio]],"") | N98: =IF(Tabla1[[#This Row],[Cantidad producida]]>Tabla1[[#This Row],[Cantidad teórica]],"SI","")
A99: 45775 | B99: 0.29166667 | C99: 0.52083333 | D99: =+IF(Tabla1[[#This Row],[Hora inicio]]<$B$1,"Mañana","Tarde") -> Mañana | E99: P | F99: =IF(Tabla1[[#This Row],[P/LC/CF/CL]]="P",Tabla1[[#This Row],[Hora fin ]]-Tabla1[[#This Row],[Hora inicio]],"") -> 0.22916667 | G99: =Tabla1[[#This Row],[Hora fin ]]-Tabla1[[#This Row],[Hora inicio]] -> 0.22916667 | H99: =WEEKNUM(Tabla1[[#This Row],[Día]]) -> 18 | J99: =IFERROR(((HOUR(Tabla1[[#This Row],[Tiempo producción]])*60+MINUTE(Tabla1[[#This Row],[Tiempo producción]]))/60)*$J$1,"") -> 9900 | K99: =IFERROR(Tabla1[[#This Row],[Cantidad producida]]/Tabla1[[#This Row],[Cantidad teórica]],"") -> 0 | L99: , se va la luz a las 12.30 | M99: =IF(Tabla1[[#This Row],[P/LC/CF/CL]]<>"P",Tabla1[[#This Row],[Hora fin ]]-Tabla1[[#This Row],[Hora inicio]],"") | N99: =IF(Tabla1[[#This Row],[Cantidad producida]]>Tabla1[[#This Row],[Cantidad teórica]],"SI","")
A100: 45775 | B100: 0.6875 | C100: 0.89583333 | D100: =+IF(Tabla1[[#This Row],[Hora inicio]]<$B$1,"Mañana","Tarde") -> Tarde | E100: P | F100: =IF(Tabla1[[#This Row],[P/LC/CF/CL]]="P",Tabla1[[#This Row],[Hora fin ]]-Tabla1[[#This Row],[Hora inicio]],"") -> 0.20833333 | G100: =Tabla1[[#This Row],[Hora fin ]]-Tabla1[[#This Row],[Hora inicio]] -> 0.20833333 | H100: =WEEKNUM(Tabla1[[#This Row],[Día]]) -> 18 | J100: =IFERROR(((HOUR(Tabla1[[#This Row],[Tiempo producción]])*60+MINUTE(Tabla1[[#This Row],[Tiempo producción]]))/60)*$J$1,"") -> 9000 | K100: =IFERROR(Tabla1[[#This Row],[Cantidad producida]]/Tabla1[[#This Row],[Cantidad teórica]],"") -> 0 | L100: , vuelve a las 16.30 | M100: =IF(Tabla1[[#This Row],[P/LC/CF/CL]]<>"P",Tabla1[[#This Row],[Hora fin ]]-Tabla1[[#This Row],[Hora inicio]],"") | N100: =IF(Tabla1[[#This Row],[Cantidad producida]]>Tabla1[[#This Row],[Cantidad teórica]],"SI","")
A101: 45776 | B101: 0.28125 | C101: 0.4375 | D101: =+IF(Tabla1[[#This Row],[Hora inicio]]<$B$1,"Mañana","Tarde") -> Mañana | E101: P | F101: =IF(Tabla1[[#This Row],[P/LC/CF/CL]]="P",Tabla1[[#This Row],[Hora fin ]]-Tabla1[[#This Row],[Hora inicio]],"") -> 0.15625 | G101: =Tabla1[[#This Row],[Hora fin ]]-Tabla1[[#This Row],[Hora inicio]] -> 0.15625 | H101: =WEEKNUM(Tabla1[[#This Row],[Día]]) -> 18 | J101: =IFERROR(((HOUR(Tabla1[[#This Row],[Tiempo producción]])*60+MINUTE(Tabla1[[#This Row],[Tiempo producción]]))/60)*$J$1,"") -> 6750 | K101: =IFERROR(Tabla1[[#This Row],[Cantidad producida]]/Tabla1[[#This Row],[Cantidad teórica]],"") -> 0 | M101: =IF(Tabla1[[#This Row],[P/LC/CF/CL]]<>"P",Tabla1[[#This Row],[Hora fin ]]-Tabla1[[#This Row],[Hora inicio]],"") | N101: =IF(Tabla1[[#This Row],[Cantidad producida]]>Tabla1[[#This Row],[Cantidad teórica]],"SI","")
A102: 45776 | B102: 0.69444444 | C102: 0.84027778 | D102: =+IF(Tabla1[[#This Row],[Hora inicio]]<$B$1,"Mañana","Tarde") -> Tarde | E102: P | F102: =IF(Tabla1[[#This Row],[P/LC/CF/CL]]="P",Tabla1[[#This Row],[Hora fin ]]-Tabla1[[#This Row],[Hora inicio]],"") -> 0.14583333 | G102: =Tabla1[[#This Row],[Hora fin ]]-Tabla1[[#This Row],[Hora inicio]] -> 0.14583333 | H102: =WEEKNUM(Tabla1[[#This Row],[Día]]) -> 18 | J102: =IFERROR(((HOUR(Tabla1[[#This Row],[Tiempo producción]])*60+MINUTE(Tabla1[[#This Row],[Tiempo producción]]))/60)*$J$1,"") -> 6300 | K102: =IFERROR(Tabla1[[#This Row],[Cantidad producida]]/Tabla1[[#This Row],[Cantidad teórica]],"") -> 0 | M102: =IF(Tabla1[[#This Row],[P/LC/CF/CL]]<>"P",Tabla1[[#This Row],[Hora fin ]]-Tabla1[[#This Row],[Hora inicio]],"") | N102: =IF(Tabla1[[#This Row],[Cantidad producida]]>Tabla1[[#This Row],[Cantidad teórica]],"SI","")
A103: 45777 | B103: 0.33333333 | C103: 0.5625 | D103: =+IF(Tabla1[[#This Row],[Hora inicio]]<$B$1,"Mañana","Tarde") -> Mañana | E103: P | F103: =IF(Tabla1[[#This Row],[P/LC/CF/CL]]="P",Tabla1[[#This Row],[Hora fin ]]-Tabla1[[#This Row],[Hora inicio]],"") -> 0.22916667 | G103: =Tabla1[[#This Row],[Hora fin ]]-Tabla1[[#This Row],[Hora inicio]] -> 0.22916667 | H103: =WEEKNUM(Tabla1[[#This Row],[Día]]) -> 18 | J103: =IFERROR(((HOUR(Tabla1[[#This Row],[Tiempo producción]])*60+MINUTE(Tabla1[[#This Row],[Tiempo producción]]))/60)*$J$1,"") -> 9900 | K103: =IFERROR(Tabla1[[#This Row],[Cantidad producida]]/Tabla1[[#This Row],[Cantidad teórica]],"") -> 0 | M103: =IF(Tabla1[[#This Row],[P/LC/CF/CL]]<>"P",Tabla1[[#This Row],[Hora fin ]]-Tabla1[[#This Row],[Hora inicio]],"") | N103: =IF(Tabla1[[#This Row],[Cantidad producida]]>Tabla1[[#This Row],[Cantidad teórica]],"SI","")
...

Sheet OEE
D1: 1800 | F1: 0.625
A2: Fecha | B2: Horas | C2: Cantidad producida | D2: Cantidad teórica | E2: Rendimiento | F2: Disponibilidad | G2: Fallo calculo disponibilidad | H2: LC | I2: OEE | J2: Semana | K2: grafic rend
A3: 45684 | B3: =SUMIFS('paradas-disp'!F:F,'paradas-disp'!A:A,Tabla3[[#This Row],[Fecha]]) -> 0 | D3: =IF(Tabla3[[#This Row],[Fecha]]<53,"",IFERROR(((HOUR(Tabla3[[#This Row],[Horas]])*60+MINUTE(Tabla3[[#This Row],[Horas]]))/60)*$D$1,"")) -> 0 | E3: =IFERROR(Tabla3[[#This Row],[Cantidad producida]]/Tabla3[[#This Row],[Cantidad teórica]],"") | F3: =IF(Tabla3[[#This Row],[Fecha]]<53,"",IFERROR(Tabla3[[#This Row],[Horas]]/$F$1,"")) -> 0 | G3: =IF(Tabla3[[#This Row],[Disponibilidad]]="","",IF(Tabla3[[#This Row],[Disponibilidad]]>1,"NO","")) | H3: =IFERROR(IF(VLOOKUP(Tabla3[[#This Row],[Fecha]],Tabla1[[Día]:[P/LC/CF/CL]],5,FALSE)="LC","SI",""),"") | I3: =IFERROR(Tabla3[[#This Row],[Disponibilidad]]*Tabla3[[#This Row],[Rendimiento]], IF(Tabla3[[#This Row],[LC]]="SI", 0, "No")) -> No | J3: =IF(Tabla3[[#This Row],[OEE]]="No","",WEEKNUM(Tabla3[[#This Row],[Fecha]])) | K3: =IFERROR(IF(Tabla3[[#This Row],[OEE]]<>"No",Tabla3[[#This Row],[OEE]]/Tabla3[[#This Row],[Disponibilidad]],""),0)
A4: 45685 | B4: =SUMIFS('paradas-disp'!F:F,'paradas-disp'!A:A,Tabla3[[#This Row],[Fecha]]) -> 0 | D4: =IF(Tabla3[[#This Row],[Fecha]]<53,"",IFERROR(((HOUR(Tabla3[[#This Row],[Horas]])*60+MINUTE(Tabla3[[#This Row],[Horas]]))/60)*$D$1,"")) -> 0 | E4: =IFERROR(Tabla3[[#This Row],[Cantidad producida]]/Tabla3[[#This Row],[Cantidad teórica]],"") | F4: =IF(Tabla3[[#This Row],[Fecha]]<53,"",IFERROR(Tabla3[[#This Row],[Horas]]/$F$1,"")) -> 0 | G4: =IF(Tabla3[[#This Row],[Disponibilidad]]="","",IF(Tabla3[[#This Row],[Disponibilidad]]>1,"NO","")) | H4: =IFERROR(IF(VLOOKUP(Tabla3[[#This Row],[Fecha]],Tabla1[[Día]:[P/LC/CF/CL]],5,FALSE)="LC","SI",""),"") | I4: =IFERROR(Tabla3[[#This Row],[Disponibilidad]]*Tabla3[[#This Row],[Rendimiento]], IF(Tabla3[[#This Row],[LC]]="SI", 0, "No")) -> No | J4: =IF(Tabla3[[#This Row],[OEE]]="No","",WEEKNUM(Tabla3[[#This Row],[Fecha]])) | K4: =IFERROR(IF(Tabla3[[#This Row],[OEE]]<>"No",Tabla3[[#This Row],[OEE]]/Tabla3[[#This Row],[Disponibilidad]],""),0)
A5: 45686 | B5: =SUMIFS('paradas-disp'!F:F,'paradas-disp'!A:A,Tabla3[[#This Row],[Fecha]]) -> 0 | D5: =IF(Tabla3[[#This Row],[Fecha]]<53,"",IFERROR(((HOUR(Tabla3[[#This Row],[Horas]])*60+MINUTE(Tabla3[[#This Row],[Horas]]))/60)*$D$1,"")) -> 0 | E5: =IFERROR(Tabla3[[#This Row],[Cantidad producida]]/Tabla3[[#This Row],[Cantidad teórica]],"") | F5: =IF(Tabla3[[#This Row],[Fecha]]<53,"",IFERROR(Tabla3[[#This Row],[Horas]]/$F$1,"")) -> 0 | G5: =IF(Tabla3[[#This Row],[Disponibilidad]]="","",IF(Tabla3[[#This Row],[Disponibilidad]]>1,"NO","")) | H5: =IFERROR(IF(VLOOKUP(Tabla3[[#This Row],[Fecha]],Tabla1[[Día]:[P/LC/CF/CL]],5,FALSE)="LC","SI",""),"") | I5: =IFERROR(Tabla3[[#This Row],[Disponibilidad]]*Tabla3[[#This Row],[Rendimiento]], IF(Tabla3[[#This Row],[LC]]="SI", 0, "No")) -> No | J5: =IF(Tabla3[[#This Row],[OEE]]="No","",WEEKNUM(Tabla3[[#This Row],[Fecha]])) | K5: =IFERROR(IF(Tabla3[[#This Row],[OEE]]<>"No",Tabla3[[#This Row],[OEE]]/Tabla3[[#This Row],[Disponibilidad]],""),0)
A6: 45687 | B6: =SUMIFS('paradas-disp'!F:F,'paradas-disp'!A:A,Tabla3[[#This Row],[Fecha]]) -> 0 | D6: =IF(Tabla3[[#This Row],[Fecha]]<53,"",IFERROR(((HOUR(Tabla3[[#This Row],[Horas]])*60+MINUTE(Tabla3[[#This Row],[Horas]]))/60)*$D$1,"")) -> 0 | E6: =IFERROR(Tabla3[[#This Row],[Cantidad producida]]/Tabla3[[#This Row],[Cantidad teórica]],"") | F6: =IF(Tabla3[[#This Row],[Fecha]]<53,"",IFERROR(Tabla3[[#This Row],[Horas]]/$F$1,"")) -> 0 | G6: =IF(Tabla3[[#This Row],[Disponibilidad]]="","",IF(Tabla3[[#This Row],[Disponibilidad]]>1,"NO","")) | H6: =IFERROR(IF(VLOOKUP(Tabla3[[#This Row],[Fecha]],Tabla1[[Día]:[P/LC/CF/CL]],5,FALSE)="LC","SI",""),"") | I6: =IFERROR(Tabla3[[#This Row],[Disponibilidad]]*Tabla3[[#This Row],[Rendimiento]], IF(Tabla3[[#This Row],[LC]]="SI", 0, "No")) -> No | J6: =IF(Tabla3[[#This Row],[OEE]]="No","",WEEKNUM(Tabla3[[#This Row],[Fecha]])) | K6: =IFERROR(IF(Tabla3[[#This Row],[OEE]]<>"No",Tabla3[[#This Row],[OEE]]/Tabla3[[#This Row],[Disponibilidad]],""),0)
A7: 45688 | B7: =SUMIFS('paradas-disp'!F:F,'paradas-disp'!A:A,Tabla3[[#This Row],[Fecha]]) -> 0 | D7: =IF(Tabla3[[#This Row],[Fecha]]<53,"",IFERROR(((HOUR(Tabla3[[#This Row],[Horas]])*60+MINUTE(Tabla3[[#This Row],[Horas]]))/60)*$D$1,"")) -> 0 | E7: =IFERROR(Tabla3[[#This Row],[Cantidad producida]]/Tabla3[[#This Row],[Cantidad teórica]],"") | F7: =IF(Tabla3[[#This Row],[Fecha]]<53,"",IFERROR(Tabla3[[#This Row],[Horas]]/$F$1,"")) -> 0 | G7: =IF(Tabla3[[#This Row],[Disponibilidad]]="","",IF(Tabla3[[#This Row],[Disponibilidad]]>1,"NO","")) | H7: =IFERROR(IF(VLOOKUP(Tabla3[[#This Row],[Fecha]],Tabla1[[Día]:[P/LC/CF/CL]],5,FALSE)="LC","SI",""),"") | I7: =IFERROR(Tabla3[[#This Row],[Disponibilidad]]*Tabla3[[#This Row],[Rendimiento]], IF(Tabla3[[#This Row],[LC]]="SI", 0, "No")) -> No | J7: =IF(Tabla3[[#This Row],[OEE]]="No","",WEEKNUM(Tabla3[[#This Row],[Fecha]])) | K7: =IFERROR(IF(Tabla3[[#This Row],[OEE]]<>"No",Tabla3[[#This Row],[OEE]]/Tabla3[[#This Row],[Disponibilidad]],""),0)
A8: 45689 | B8: =SUMIFS('paradas-disp'!F:F,'paradas-disp'!A:A,Tabla3[[#This Row],[Fecha]]) -> 0 | D8: =IF(Tabla3[[#This Row],[Fecha]]<53,"",IFERROR(((HOUR(Tabla3[[#This Row],[Horas]])*60+MINUTE(Tabla3[[#This Row],[Horas]]))/60)*$D$1,"")) -> 0 | E8: =IFERROR(Tabla3[[#This Row],[Cantidad producida]]/Tabla3[[#This Row],[Cantidad teórica]],"") | F8: =IF(Tabla3[[#This Row],[Fecha]]<53,"",IFERROR(Tabla3[[#This Row],[Horas]]/$F$1,"")) -> 0 | G8: =IF(Tabla3[[#This Row],[Disponibilidad]]="","",IF(Tabla3[[#This Row],[Disponibilidad]]>1,"NO","")) | H8: =IFERROR(IF(VLOOKUP(Tabla3[[#This Row],[Fecha]],Tabla1[[Día]:[P/LC/CF/CL]],5,FALSE)="LC","SI",""),"") | I8: =IFERROR(Tabla3[[#This Row],[Disponibilidad]]*Tabla3[[#This Row],[Rendimiento]], IF(Tabla3[[#This Row],[LC]]="SI", 0, "No")) -> No | J8: =IF(Tabla3[[#This Row],[OEE]]="No","",WEEKNUM(Tabla3[[#This Row],[Fecha]])) | K8: =IFERROR(IF(Tabla3[[#This Row],[OEE]]<>"No",Tabla3[[#This Row],[OEE]]/Tabla3[[#This Row],[Disponibilidad]],""),0)
A9: 45690 | B9: =SUMIFS('paradas-disp'!F:F,'paradas-disp'!A:A,Tabla3[[#This Row],[Fecha]]) -> 0 | D9: =IF(Tabla3[[#This Row],[Fecha]]<53,"",IFERROR(((HOUR(Tabla3[[#This Row],[Horas]])*60+MINUTE(Tabla3[[#This Row],[Horas]]))/60)*$D$1,"")) -> 0 | E9: =IFERROR(Tabla3[[#This Row],[Cantidad producida]]/Tabla3[[#This Row],[Cantidad teórica]],"") | F9: =IF(Tabla3[[#This Row],[Fecha]]<53,"",IFERROR(Tabla3[[#This Row],[Horas]]/$F$1,"")) -> 0 | G9: =IF(Tabla3[[#This Row],[Disponibilidad]]="","",IF(Tabla3[[#This Row],[Disponibilidad]]>1,"NO","")) | H9: =IFERROR(IF(VLOOKUP(Tabla3[[#This Row],[Fecha]],Tabla1[[Día]:[P/LC/CF/CL]],5,FALSE)="LC","SI",""),"") | I9: =IFERROR(Tabla3[[#This Row],[Disponibilidad]]*Tabla3[[#This Row],[Rendimiento]], IF(Tabla3[[#This Row],[LC]]="SI", 0, "No")) -> No | J9: =IF(Tabla3[[#This Row],[OEE]]="No","",WEEKNUM(Tabla3[[#This Row],[Fecha]])) | K9: =IFERROR(IF(Tabla3[[#This Row],[OEE]]<>"No",Tabla3[[#This Row],[OEE]]/Tabla3[[#This Row],[Disponibilidad]],""),0)
A10: 45691 | B10: =SUMIFS('paradas-disp'!F:F,'paradas-disp'!A:A,Tabla3[[#This Row],[Fecha]]) -> 0 | D10: =IF(Tabla3[[#This Row],[Fecha]]<53,"",IFERROR(((HOUR(Tabla3[[#This Row],[Horas]])*60+MINUTE(Tabla3[[#This Row],[Horas]]))/60)*$D$1,"")) -> 0 | E10: =IFERROR(Tabla3[[#This Row],[Cantidad producida]]/Tabla3[[#This Row],[Cantidad teórica]],"") | F10: =IF(Tabla3[[#This Row],[Fecha]]<53,"",IFERROR(Tabla3[[#This Row],[Horas]]/$F$1,"")) -> 0 | G10: =IF(Tabla3[[#This Row],[Disponibilidad]]="","",IF(Tabla3[[#This Row],[Disponibilidad]]>1,"NO","")) | H10: =IFERROR(IF(VLOOKUP(Tabla3[[#This Row],[Fecha]],Tabla1[[Día]:[P/LC/CF/CL]],5,FALSE)="LC","SI",""),"") | I10: =IFERROR(Tabla3[[#This Row],[Disponibilidad]]*Tabla3[[#This Row],[Rendimiento]], IF(Tabla3[[#This Row],[LC]]="SI", 0, "No")) -> No | J10: =IF(Tabla3[[#This Row],[OEE]]="No","",WEEKNUM(Tabla3[[#This Row],[Fecha]])) | K10: =IFERROR(IF(Tabla3[[#This Row],[OEE]]<>"No",Tabla3[[#This Row],[OEE]]/Tabla3[[#This Row],[Disponibilidad]],""),0)
A11: 45692 | B11: =SUMIFS('paradas-disp'!F:F,'paradas-disp'!A:A,Tabla3[[#This Row],[Fecha]]) -> 0.090277778 | C11: =SUMIFS('paradas-disp'!I:I,'paradas-disp'!A:A,Tabla3[[#This Row],[Fecha]]) -> 2754 | D11: =IF(Tabla3[[#This Row],[Fecha]]<53,"",IFERROR(((HOUR(Tabla3[[#This Row],[Horas]])*60+MINUTE(Tabla3[[#This Row],[Horas]]))/60)*$D$1,"")) -> 3900 | E11: =IFERROR(Tabla3[[#This Row],[Cantidad producida]]/Tabla3[[#This Row],[Cantidad teórica]],"") -> 0.70615385 | F11: =IF(Tabla3[[#This Row],[Fecha]]<53,"",IFERROR(Tabla3[[#This Row],[Horas]]/$F$1,"")) -> 0.14444444 | G11: =IF(Tabla3[[#This Row],[Disponibilidad]]="","",IF(Tabla3[[#This Row],[Disponibilidad]]>1,"NO","")) | H11: =IFERROR(IF(VLOOKUP(Tabla3[[#This Row],[Fecha]],Tabla1[[Día]:[P/LC/CF/CL]],5,FALSE)="LC","SI",""),"") | I11: =IFERROR(Tabla3[[#This Row],[Disponibilidad]]*Tabla3[[#This Row],[Rendimiento]], IF(Tabla3[[#This Row],[LC]]="SI", 0, "No")) -> 0.102 | J11: =IF(Tabla3[[#This Row],[OEE]]="No","",WEEKNUM(Tabla3[[#This Row],[Fecha]])) -> 6 | K11: =IFERROR(IF(Tabla3[[#This Row],[OEE]]<>"No",Tabla3[[#This Row],[OEE]]/Tabla3[[#This Row],[Disponibilidad]],""),0) -> 0.70615385
A12: 45693 | B12: =SUMIFS('paradas-disp'!F:F,'paradas-disp'!A:A,Tabla3[[#This Row],[Fecha]]) -> 0.47569444 | C12: =SUMIFS('paradas-disp'!I:I,'paradas-disp'!A:A,Tabla3[[#This Row],[Fecha]]) -> 13140 | D12: =IF(Tabla3[[#This Row],[Fecha]]<53,"",IFERROR(((HOUR(Tabla3[[#This Row],[Horas]])*60+MINUTE(Tabla3[[#This Row],[Horas]]))/60)*$D$1,"")) -> 20550 | E12: =IFERROR(Tabla3[[#This Row],[Cantidad producida]]/Tabla3[[#This Row],[Cantidad teórica]],"") -> 0.63941606 | F12: =IF(Tabla3[[#This Row],[Fecha]]<53,"",IFERROR(Tabla3[[#This Row],[Horas]]/$F$1,"")) -> 0.76111111 | G12: =IF(Tabla3[[#This Row],[Disponibilidad]]="","",IF(Tabla3[[#This Row],[Disponibilidad]]>1,"NO","")) | H12: =IFERROR(IF(VLOOKUP(Tabla3[[#This Row],[Fecha]],Tabla1[[Día]:[P/LC/CF/CL]],5,FALSE)="LC","SI",""),"") | I12: =IFERROR(Tabla3[[#This Row],[Disponibilidad]]*Tabla3[[#This Row],[Rendimiento]], IF(Tabla3[[#This Row],[LC]]="SI", 0, "No")) -> 0.48666667 | J12: =IF(Tabla3[[#This Row],[OEE]]="No","",WEEKNUM(Tabla3[[#This Row],[Fecha]])) -> 6 | K12: =IFERROR(IF(Tabla3[[#This Row],[OEE]]<>"No",Tabla3[[#This Row],[OEE]]/Tabla3[[#This Row],[Disponibilidad]],""),0) -> 0.63941606
A13: 45694 | B13: =SUMIFS('paradas-disp'!F:F,'paradas-disp'!A:A,Tabla3[[#This Row],[Fecha]]) -> 0.34375 | C13: =SUMIFS('paradas-disp'!I:I,'paradas-disp'!A:A,Tabla3[[#This Row],[Fecha]]) -> 10938 | D13: =IF(Tabla3[[#This Row],[Fecha]]<53,"",IFERROR(((HOUR(Tabla3[[#This Row],[Horas]])*60+MINUTE(Tabla3[[#This Row],[Horas]]))/60)*$D$1,"")) -> 14850 | E13: =IFERROR(Tabla3[[#This Row],[Cantidad producida]]/Tabla3[[#This Row],[Cantidad teórica]],"") -> 0.73656566 | F13: =IF(Tabla3[[#This Row],[Fecha]]<53,"",IFERROR(Tabla3[[#This Row],[Horas]]/$F$1,"")) -> 0.55 | G13: =IF(Tabla3[[#This Row],[Disponibilidad]]="","",IF(Tabla3[[#This Row],[Disponibilidad]]>1,"NO","")) | H13: =IFERROR(IF(VLOOKUP(Tabla3[[#This Row],[Fecha]],Tabla1[[Día]:[P/LC/CF/CL]],5,FALSE)="LC","SI",""),"") | I13: =IFERROR(Tabla3[[#This Row],[Disponibilidad]]*Tabla3[[#This Row],[Rendimiento]], IF(Tabla3[[#This Row],[LC]]="SI", 0, "No")) -> 0.40511111 | J13: =IF(Tabla3[[#This Row],[OEE]]="No","",WEEKNUM(Tabla3[[#This Row],[Fecha]])) -> 6 | K13: =IFERROR(IF(Tabla3[[#This Row],[OEE]]<>"No",Tabla3[[#This Row],[OEE]]/Tabla3[[#This Row],[Disponibilidad]],""),0) -> 0.73656566
A14: 45695 | B14: =SUMIFS('paradas-disp'!F:F,'paradas-disp'!A:A,Tabla3[[#This Row],[Fecha]]) -> 0.34722222 | C14: =SUMIFS('paradas-disp'!I:I,'paradas-disp'!A:A,Tabla3[[#This Row],[Fecha]]) -> 8592 | D14: =IF(Tabla3[[#This Row],[Fecha]]<53,"",IFERROR(((HOUR(Tabla3[[#This Row],[Horas]])*60+MINUTE(Tabla3[[#This Row],[Horas]]))/60)*$D$1,"")) -> 15000 | E14: =IFERROR(Tabla3[[#This Row],[Cantidad producida]]/Tabla3[[#This Row],[Cantidad teórica]],"") -> 0.5728 | F14: =IF(Tabla3[[#This Row],[Fecha]]<53,"",IFERROR(Tabla3[[#This Row],[Horas]]/$F$1,"")) -> 0.55555556 | G14: =IF(Tabla3[[#This Row],[Disponibilidad]]="","",IF(Tabla3[[#This Row],[Disponibilidad]]>1,"NO","")) | H14: =IFERROR(IF(VLOOKUP(Tabla3[[#This Row],[Fecha]],Tabla1[[Día]:[P/LC/CF/CL]],5,FALSE)="LC","SI",""),"") | I14: =IFERROR(Tabla3[[#This Row],[Disponibilidad]]*Tabla3[[#This Row],[Rendimiento]], IF(Tabla3[[#This Row],[LC]]="SI", 0, "No")) -> 0.31822222 | J14: =IF(Tabla3[[#This Row],[OEE]]="No","",WEEKNUM(Tabla3[[#This Row],[Fecha]])) -> 6 | K14: =IFERROR(IF(Tabla3[[#This Row],[OEE]]<>"No",Tabla3[[#This Row],[OEE]]/Tabla3[[#This Row],[Disponibilidad]],""),0) -> 0.5728
A15: 45696 | B15: =SUMIFS('paradas-disp'!F:F,'paradas-disp'!A:A,Tabla3[[#This Row],[Fecha]]) -> 0 | D15: =IF(Tabla3[[#This Row],[Fecha]]<53,"",IFERROR(((HOUR(Tabla3[[#This Row],[Horas]])*60+MINUTE(Tabla3[[#This Row],[Horas]]))/60)*$D$1,"")) -> 0 | E15: =IFERROR(Tabla3[[#This Row],[Cantidad producida]]/Tabla3[[#This Row],[Cantidad teórica]],"") | F15: =IF(Tabla3[[#This Row],[Fecha]]<53,"",IFERROR(Tabla3[[#This Row],[Horas]]/$F$1,"")) -> 0 | G15: =IF(Tabla3[[#This Row],[Disponibilidad]]="","",IF(Tabla3[[#This Row],[Disponibilidad]]>1,"NO","")) | H15: =IFERROR(IF(VLOOKUP(Tabla3[[#This Row],[Fecha]],Tabla1[[Día]:[P/LC/CF/CL]],5,FALSE)="LC","SI",""),"") | I15: =IFERROR(Tabla3[[#This Row],[Disponibilidad]]*Tabla3[[#This Row],[Rendimiento]], IF(Tabla3[[#This Row],[LC]]="SI", 0, "No")) -> No | J15: =IF(Tabla3[[#This Row],[OEE]]="No","",WEEKNUM(Tabla3[[#This Row],[Fecha]])) | K15: =IFERROR(IF(Tabla3[[#This Row],[OEE]]<>"No",Tabla3[[#This Row],[OEE]]/Tabla3[[#This Row],[Disponibilidad]],""),0)
A16: 45697 | B16: =SUMIFS('paradas-disp'!F:F,'paradas-disp'!A:A,Tabla3[[#This Row],[Fecha]]) -> 0 | D16: =IF(Tabla3[[#This Row],[Fecha]]<53,"",IFERROR(((HOUR(Tabla3[[#This Row],[Horas]])*60+MINUTE(Tabla3[[#This Row],[Horas]]))/60)*$D$1,"")) -> 0 | E16: =IFERROR(Tabla3[[#This Row],[Cantidad producida]]/Tabla3[[#This Row],[Cantidad teórica]],"") | F16: =IF(Tabla3[[#This Row],[Fecha]]<53,"",IFERROR(Tabla3[[#This Row],[Horas]]/$F$1,"")) -> 0 | G16: =IF(Tabla3[[#This Row],[Disponibilidad]]="","",IF(Tabla3[[#This Row],[Disponibilidad]]>1,"NO","")) | H16: =IFERROR(IF(VLOOKUP(Tabla3[[#This Row],[Fecha]],Tabla1[[Día]:[P/LC/CF/CL]],5,FALSE)="LC","SI",""),"") | I16: =IFERROR(Tabla3[[#This Row],[Disponibilidad]]*Tabla3[[#This Row],[Rendimiento]], IF(Tabla3[[#This Row],[LC]]="SI", 0, "No")) -> No | J16: =IF(Tabla3[[#This Row],[OEE]]="No","",WEEKNUM(Tabla3[[#This Row],[Fecha]])) | K16: =IFERROR(IF(Tabla3[[#This Row],[OEE]]<>"No",Tabla3[[#This Row],[OEE]]/Tabla3[[#This Row],[Disponibilidad]],""),0)
A17: 45698 | B17: =SUMIFS('paradas-disp'!F:F,'paradas-disp'!A:A,Tabla3[[#This Row],[Fecha]]) -> 0.055555556 | C17: =SUMIFS('paradas-disp'!I:I,'paradas-disp'!A:A,Tabla3[[#This Row],[Fecha]]) -> 384 | D17: =IF(Tabla3[[#This Row],[Fecha]]<53,"",IFERROR(((HOUR(Tabla3[[#This Row],[Horas]])*60+MINUTE(Tabla3[[#This Row],[Horas]]))/60)*$D$1,"")) -> 2400 | E17: =IFERROR(Tabla3[[#This Row],[Cantidad producida]]/Tabla3[[#This Row],[Cantidad teórica]],"") -> 0.16 | F17: =IF(Tabla3[[#This Row],[Fecha]]<53,"",IFERROR(Tabla3[[#This Row],[Horas]]/$F$1,"")) -> 0.088888889 | G17: =IF(Tabla3[[#This Row],[Disponibilidad]]="","",IF(Tabla3[[#This Row],[Disponibilidad]]>1,"NO","")) | H17: =IFERROR(IF(VLOOKUP(Tabla3[[#This Row],[Fecha]],Tabla1[[Día]:[P/LC/CF/CL]],5,FALSE)="LC","SI",""),"") | I17: =IFERROR(Tabla3[[#This Row],[Disponibilidad]]*Tabla3[[#This Row],[Rendimiento]], IF(Tabla3[[#This Row],[LC]]="SI", 0, "No")) -> 0.014222222 | J17: =IF(Tabla3[[#This Row],[OEE]]="No","",WEEKNUM(Tabla3[[#This Row],[Fecha]])) -> 7 | K17: =IFERROR(IF(Tabla3[[#This Row],[OEE]]<>"No",Tabla3[[#This Row],[OEE]]/Tabla3[[#This Row],[Disponibilidad]],""),0) -> 0.16
A18: 45699 | B18: =SUMIFS('paradas-disp'!F:F,'paradas-disp'!A:A,Tabla3[[#This Row],[Fecha]]) -> 0.28125 | C18: =SUMIFS('paradas-disp'!I:I,'paradas-disp'!A:A,Tabla3[[#This Row],[Fecha]]) -> 5820 | D18: =IF(Tabla3[[#This Row],[Fecha]]<53,"",IFERROR(((HOUR(Tabla3[[#This Row],[Horas]])*60+MINUTE(Tabla3[[#This Row],[Horas]]))/60)*$D$1,"")) -> 12150 | E18: =IFERROR(Tabla3[[#This Row],[Cantidad producida]]/Tabla3[[#This Row],[Cantidad teórica]],"") -> 0.47901235 | F18: =IF(Tabla3[[#This Row],[Fecha]]<53,"",IFERROR(Tabla3[[#This Row],[Horas]]/$F$1,"")) -> 0.45 | G18: =IF(Tabla3[[#This Row],[Disponibilidad]]="","",IF(Tabla3[[#This Row],[Disponibilidad]]>1,"NO","")) | H18: =IFERROR(IF(VLOOKUP(Tabla3[[#This Row],[Fecha]],Tabla1[[Día]:[P/LC/CF/CL]],5,FALSE)="LC","SI",""),"") | I18: =IFERROR(Tabla3[[#This Row],[Disponibilidad]]*Tabla3[[#This Row],[Rendimiento]], IF(Tabla3[[#This Row],[LC]]="SI", 0, "No")) -> 0.21555556 | J18: =IF(Tabla3[[#This Row],[OEE]]="No","",WEEKNUM(Tabla3[[#This Row],[Fecha]])) -> 7 | K18: =IFERROR(IF(Tabla3[[#This Row],[OEE]]<>"No",Tabla3[[#This Row],[OEE]]/Tabla3[[#This Row],[Disponibilidad]],""),0) -> 0.47901235
